<sdf version="1.0">
  <model name="SAM">

    <link name="world"></link>

    <joint name="ground_fixed" type="fixed">  
      <parent>world</parent>   
      <child>ground</child> 
      <axis>
	<xyz expressed_in="__model__">0 0 0</xyz>
      </axis>
    </joint> 

    <link name="ground">   
      <pose>0 0 0 0 0 0</pose>
      <inertial>    
      	<mass>0.0</mass>  
	<inertia>
	  <ixx>0.0</ixx>
	  <ixy>0.0</ixy>
	  <ixz>0.0</ixz>
	  <iyy>0.0</iyy>
	  <iyz>0.0</iyz>
	  <izz>0.0</izz>
	</inertia>
      </inertia>
      <visual name="ground_visual>
        <pose> 0 0 0 0 0 0 </pose>
        <geometry>
          <mesh> 
            <scale>1 1 1</scale>
            <url>filename="../stl/dummy_ball_d20.STL" <!--MESHMESHMESHMESHEMSHEMSHEMSHEMSHEMSHEMSHEMSHEMSHEMSH-->
          </mesh>
        </geometry>
      </visual>
    </link>  
        
    <joint name="rope_J_connector_yaw" type="revolute">
      <pose>0 0 0 0 0 0</pose>
      <parent>ground</parent>
      <child>dummy3</child>
      <axis>
	<xyz espressed_in="__model__">0 0 1</xyz>
      </axis>
    </joint>
	    
    <link name="dummy3"> 
      <pose> 0 0 0 0 0 0 </pose>
      <inertial>
        <mass>0.0001</mass>
        <inertia>
	  <ixx>0.0001</ixx>
          <iyy>0.0001</iyy>
          <izz>0.0001</izz>
          <ixy>     0</ixy>
          <ixz>     0</ixz>
          <iyz>     0</iyz>
	<inertia>
      </inertial>		
    </link>
     
    <joint name="rope_J_connector_pitch" type="revolute">
      <pose> 0 0 0 0 0 0 </pose>
      <parent>dummy3</parent>
      <child>dummy4</child>
      <axis>
	<xyz espressed_in="__model__">0 1 0</xyz>
      </axis>
      <damping>0.1</damping>        
    </joint>
    
    <link name="dummy4">
      <pose> 0 0 0 0 0 0 </pose>
      <inertial>
        <mass>0.0001</mass>
        <inertia>
	  <ixx>0.0001</ixx>
	  <iyy>0.0001</iyy> 
	  <izz>0.0001</izz> 
	  <ixy>     0</ixy> 
	  <ixz>     0</ixz> 
	  <iyz>     0</iyz>
	</inertia>
      </inertial>		
    </link>

    <joint name="rope_J_connector_roll" type="revolute">
      <pose> 0 0 0 0 0 0 </pose>
      <parent>dummy4</parent>
      <child>dummy5</child>
      <axis>
	 <xyz espressed_in="__model__">1 0 0</xyz>
      </axis>       
      <damping>0.1</damping>        
    </joint>

    <link name="dummy5">
      <pose> 0 0 0 0 0 0 </pose>
      <inertial>
        <mass>0.0001</mass>
	<inertia>
	  <ixx>0.0001</ixx>
	  <iyy>0.0001</iyy> 
	  <izz>0.0001</izz> 
	  <ixy>     0</ixy> 
	  <ixz>     0</ixz> 
	  <iyz>     0</iyz>
	</inertia>
      </inertial>
    </link>    

    <joint name="connector_J_platform_x" type="prismatic">
      <pose> 0 0 0 0 0 0 </pose>
      <parent>dummy5</parent>
      <child>dummy6</child>
      <axis>
	 <xyz espressed_in="__model__">1 0 0</xyz>
      </axis> 
    </joint>
    
    <link name="dummy6"> 
      <pose> 0 0 0 0 0 0 </pose>
      <inertial>
        <mass>0.0001</mass>
        <inertia>
	  <ixx>0.0001</ixx>
	  <iyy>0.0001</iyy> 
	  <izz>0.0001</izz> 
	  <ixy>     0</ixy> 
	  <ixz>     0</ixz> 
	  <iyz>     0</iyz>
	</inertia>
      </inertial>
    </link>

    <joint name="connector_J_platform_y" type="prismatic">
      <pose> 0 0 0 0 0 0 </pose>
      <parent>dummy6</parent>
      <child>dummy7</child>
      <axis>
	<xyz espressed_in="__model__">0 1 0</xyz>
      </axis> 
    </joint>
    
    <link name="dummy7">
      <pose> 0 0 0 0 0 0 </pose> 
      <inertial>
        <mass>0.0001</mass>
        <inertia>
	  <ixx>0.0001</ixx>
	  <iyy>0.0001</iyy> 
	  <izz>0.0001</izz> 
	  <ixy>     0</ixy> 
	  <ixz>     0</ixz> 
	  <iyz>     0</iyz>
	</inertia>
      </inertial>
    </link>
    
    <joint name="connector_J_platform_z" type="prismatic"><!--type="prismatic">-->
      <pose> 0 0 0 0 0 0 </pose>
      <parent>dummy7</parent>
      <child>platform"</child>
      <axis>
	<xyz espressed_in="__model__">0 0 1</xyz>
      </axis>
    </joint>
	
	
    <link name="platform">
      <tcp number="0" /><!--checkcheckcheckcheckcheckcheck-->
      <pose> 0 0 0 0 0 0 </pose>
      <inertial>
        <mass>30</mass>  <!--3-->
        <inertia>
	  <ixx>4.2</ixx>
	  <iyy>4.2</iyy> 
	  <izz>8.4</izz> 
	  <ixy>  0</ixy> 
	  <ixz>  0</ixz> 
	  <iyz>  0</iyz>
        </inertia>
      </inertial>
      <visual name="platform_visual">
	<pose> 0 0 0 1.570796327 0 0 </pose>
        <geometry>
	  <mesh>
            <stage>1 1 1</stage>
	    <url> filename="../stl/platform_d1000_h30.STL"/><!-- 20mm?--><!--MESHMESHMESHMESHEMSHEMSHEMSHEMSHEMSHEMSHEMSHEMSHEMSH-->
	  </mesh>
        </geometry>
      </visual>
      <collision>
        <pose> 0 0 0 1.5707963267 0 0 </pose>
        <geometry>
          <capsule a="0 0.0 0.0" b="0 0.0 0.0" radius="0.05"/><!--MESHMESHMESHMESHEMSHEMSHEMSHEMSHEMSHEMSHEMSHEMSHEMSH-->
        </geometry>
      </collision>
    </link>	
   
   
   
    
<!--manipulator-->
    
    <joint name="lwr_joint_1" type="revolute">
      <pose>0.218 0.10 -0.11 0 3.141592653589793 -2.748893571891069</pose>
      <parent>platform</parent>
      <child>lwr_link_1</child> 
      <axis>
	<xyz espressed_in="__model__">0 0 1</xyz>
      </axis>
    </joint>

    <link name="lwr_link_1">
      <pose>0 0.0170 0.1409 1.3 0 0</pose>
      <inertial>  
        <mass>2.7082</mass>
        <inertia>
	  <ixx> 0.0777</ixx>
	  <iyy> 0.0774</iyy> 
	  <izz> 0.0058</izz> 
	  <ixy>      0</ixy> 
	  <ixz>      0</ixz> 
	  <iyz>-0.0086</iyz>
        </inertia>
      </inertial>
      <visual>
        <pose>0 0 0.20 -1.570796327 0 0</pose>
        <geometry>
          <mesh>
            <scale>1 1 1</scale>
            <filename="../stl/lbr_kuka_link1.stl"/><!--MESHMESHMESHMESHEMSHEMSHEMSHEMSHEMSHEMSHEMSHEMSHEMSH-->
          </mesh>
        </geometry>
      </visual>
    </link>
    
    <joint name="lwr_joint_2" type="revolute">
      <pose>0 0 0.2 1.570796327 0 0</pose>
      <parent>lwr_link_1</parent>
      <child>lwr_link_2</child> 
      <axis>
	<xyz espressed_in="__model__">0 0 1</xyz>
      </axis>
    </joint>

    <link name="lwr_link_2">
      <pose>0.0005 0.0420 0 0 0 0</pose>
        <inertial>  
          <mass>2.7100</mass>
	  <inertia>
	    <ixx> 0.0310</ixx>
	    <iyy> 0.0053</iyy> 
	    <izz> 0.0311</izz> 
	    <ixy>-0.0001</ixy> 
	    <ixz>      0</ixz> 
	    <iyz> 0.0041</iyz>
          </inertia>
        </inertial>
        <visual>
          <pose>0 0 0 -1.570796327 0 0</pose>
          <geometry>
            <mesh>
              <scale>1 1 1</scale>
              <url><filename="../stl/lbr_kuka_link2.stl"/><!--MESHMESHMESHMESHEMSHEMSHEMSHEMSHEMSHEMSHEMSHEMSHEMSH-->
            </mesh>
          </geometry>
        </visual>
    </link>
    
    
    <joint name="lwr_joint_3" type="revolute">
      <pose>0 0.2 0 -1.570796327 0 0</pose>
      <parent>lwr_link_2</parent>
      <child>lwr_link_3</child> 
      <axis>
	<xyz espressed_in="__model__">0 0 1</xyz>
      </axis>
    </joint>

    <link name="lwr_link_3">
        <pose>0.0004 -0.0001 0.2393 0 0 0</pose>
	<inertial>  
          <mass>2.5374</mass>
	  <inertia>
	    <ixx> 0.1595</ixx>
	    <iyy> 0.1595</iyy> 
	    <izz> 0.0049</izz> 
	    <ixy>      0</ixy> 
	    <ixz>-0.0002</ixz> 
	    <iyz> 0.0012</iyz>
          </inertia>
        </inertial>
        <visual>
          <pose>0 0 0.2 -1.570796327 0 0</pose>
          <geometry>
            <mesh>
	      <scale>1 1 1</scale>
              <url> filename="../stl/lbr_kuka_link3.stl"/> <!--MESHMESHMESHMESHEMSHEMSHEMSHEMSHEMSHEMSHEMSHEMSHEMSH-->
	    <mesh>
          </geometry>
        </visual>
    </link>
   
  
    <joint name="lwr_joint_4" type="revolute">
      <pose>0 0 0.2 -1.570796327 0 0</pose>
      <parent>lwr_link_3</parent>
      <child>lwr_link_4</child> 
      <axis>
	<xyz espressed_in="__model__">0 0 1</xyz>
      </axis>
    </joint>

    <link name="lwr_link_4">
      <pose>-0.0014 -0.0435 -0.0001 0 0 0</pose>
      <inertial>  
        <mass>2.5053</mass>
        <inertia>
	  <ixx> 0.0333</ixx>
	  <iyy> 0.0049</iyy> 
	  <izz> 0.0284</izz> 
	  <ixy>-0.0002</ixy> 
	  <ixz>      0</ixz> 
	  <iyz>-0.0033</iyz>
        </inertia>
      </inertial>
      <visual>
        <pose>0 0 0 -1.570796327 0 0</pose>
        <geometry>
          <mesh> 
            <scale>1 1 1</scale>
            <url>filename="../stl/lbr_kuka_link4.stl"/> <!--MESHMESHMESHMESHEMSHEMSHEMSHEMSHEMSHEMSHEMSHEMSHEMSH-->
          </mesh>
        </geometry>
      </visual>
    </link> 
    
    
    <joint name="lwr_joint_5" type="revolute">
      <pose>0 -0.19 0 1.570796327 0 0</pose>
      <parent>lwr_link_4</parent>
      <child>lwr_link_5</child> 
      <axis>
	<xyz espressed_in="__model__">0 0 1</xyz>
      </axis>
    </joint>

    <link name="lwr_link_5">
      <pose>-0.0005 0.0128 0.2126 0 0 0</pose>
      <inertial>  
        <mass>1.3028</mass>
        <inertia>
	  <ixx> 0.0852</ixx>
	  <iyy> 0.0850</iyy> 
	  <izz> 0.0264</izz> 
	  <ixy>      0</ixy> 
	  <ixz> 0.0001</ixz> 
	  <iyz>-0.0069</iyz>
        </inertia>
      </inertial>
      <visual>
        <pose>0 0 0.2 -1.570796327 0 0</pose>
        <geometry>
          <mesh>
	    <scale>1 1 1</scale>
            <url> filename="../stl/lbr_kuka_link5.stl"/> <!--MESHMESHMESHMESHEMSHEMSHEMSHEMSHEMSHEMSHEMSHEMSHEMSH-->
          </mesh>
        </geometry>
      </visual>
    </link> 
    

    <joint name="lwr_joint_6" type="revolute">
      <pose>0 0 0.2 1.570796327 0 0</pose>
      <parent>lwr_link_5</parent>
      <child>lwr_link_6</child> 
      <axis>
	<xyz espressed_in="__model__">0 0 1</xyz>
      </axis>
    </joint>

    <link name="lwr_link_6">
      <pose>0.0005 0.0180 -0.0154 0 0 0</pose>
      <inertial>    
        <mass>1.5686</mass>
        <inertia>
	  <ixx>0.0043</ixx>
	  <iyy>0.0034</iyy> 
	  <izz>0.0035</izz> 
	  <ixy>     0</ixy> 
	  <ixz>     0</ixz> 
	  <iyz>0.0005</iyz>
        </inertia>
      </inertial>
      <visual>
        <pose>0 0 0 0 3.141592654 0</pose>
        <geometry>
          <mesh>
	    <scale>1 1 1</scale>
            <url>filename="../stl/lbr_kuka_link6.stl"/><!--MESHMESHMESHMESHEMSHEMSHEMSHEMSHEMSHEMSHEMSHEMSHEMSH-->
	  </mesh> 
        </geometry>
      </visual> 
    </link> 

    
    <joint name="lwr_joint_7" type="revolute">
      <pose>0 0 0 -1.570796327 0 0</pose>
      <parent>lwr_link_6</parent>
      <child>lwr_link_7</child> 
      <axis>
	<xyz espressed_in="__model__">0 0 1</xyz>
      </axis>
    </joint>

    <link name="lwr_link_7">
      <tcp number="1" /><!--checkcheckcheckcheckcheckcheck-->
      <pose>-0.0270 -0.0070 0.1540 0 0 0</pose>
      <inertial>  
        <mass>2</mass>
        <inertia>
	  <ixx> 0.1643</ixx>
	  <iyy> 0.1819</iyy> 
	  <izz> 0.0730</izz> 
	  <ixy>-0.0007</ixy> 
	  <ixz> 0.0095</ixz> 
	  <iyz> 0.0041</iyz>
        </inertia>
      </inertial>
      <visual>
        <pose>0 0 0 1.570796327 3.141592654 0</pose>
        <geometry>
          <mesh>
	    <scale>1 1 1</scale>
            <url> filename="../stl/lbr_kuka_link7.stl"/><!--MESHMESHMESHMESHEMSHEMSHEMSHEMSHEMSHEMSHEMSHEMSHEMSH-->
          </mesh>
        </geometry>
      </visual>
    </link>

</robot>